<sdf version='1.6'>
  <model name='mbot'>
    <link name='base_link'>
      <pose frame=''>0 0 0 0 -0 0</pose>
      <inertial>
        <pose frame=''>-2e-06 3e-06 0.000729 0 -0 0</pose>
        <mass>40.241</mass>
        <inertia>
          <ixx>1.52278</ixx>
          <ixy>8.39902e-06</ixy>
          <ixz>-4.11607e-05</ixz>
          <iyy>3.15312</iyy>
          <iyz>0.0074909</iyz>
          <izz>3.07235</izz>
        </inertia>
      </inertial>
      <collision name='base_link_collision'>
        <pose frame=''>0.05 0 0.4 0 -0 0</pose>
        <geometry>
          <cylinder>
            <length>0.515</length>
            <radius>0.23</radius>
          </cylinder>
        </geometry>
        <surface>
          <contact>
            <ode/>
          </contact>
          <friction>
            <ode/>
          </friction>
        </surface>
      </collision>
      <collision name='base_link_fixed_joint_lump__left_arm_base_link_collision_1'>
        <pose frame=''>-0.006972 0.187 0.625729 1.5708 1.04934 3.14159</pose>
        <geometry>
          <box>
            <size>0.154 0.177 0.094</size>
          </box>
        </geometry>
      </collision>
      <visual name='base_link_visual'>
        <pose frame=''>0 0 0.025 0 -0 0</pose>
        <geometry>
          <mesh>
            <scale>1 1 1</scale>
            <uri>model://mbot_description/meshes/body/mbot_body.dae</uri>
          </mesh>
        </geometry>
        <material>
          <script>
            <name>Gazebo/DepthMapVS</name>
            <uri>file://media/materials/scripts/gazebo.material</uri>
          </script>
        </material>
      </visual>
      <visual name='base_link_fixed_joint_lump__base_laser_rear_link_visual_1'>
        <pose frame=''>-0.2795 0 0.1335 -3.14159 -0 -3.14159</pose>
        <geometry>
          <mesh>
            <scale>1 1 1</scale>
            <uri>model://mbot_description/meshes/sensors/hokuyo.dae</uri>
          </mesh>
        </geometry>
        <material>
          <script>
            <uri>__default__</uri>
            <name>__default__</name>
          </script>
        </material>
      </visual>
      <visual name='base_link_fixed_joint_lump__base_laser_front_link_visual_2'>
        <pose frame=''>0.2785 0 0.1335 0 -0 0</pose>
        <geometry>
          <mesh>
            <scale>1 1 1</scale>
            <uri>model://mbot_description/meshes/sensors/hokuyo.dae</uri>
          </mesh>
        </geometry>
        <material>
          <script>
            <uri>__default__</uri>
            <name>__default__</name>
          </script>
        </material>
      </visual>
      <visual name='base_link_fixed_joint_lump__left_arm_base_link_visual_3'>
        <pose frame=''>0.003 0.14 0.62 1.5708 1.04934 3.14159</pose>
        <geometry>
          <mesh>
            <scale>1 1 1</scale>
            <uri>model://cyton_gamma_1500_description/meshes/base.dae</uri>
          </mesh>
        </geometry>
      </visual>
      <velocity_decay/>
      <gravity>1</gravity>
      <velocity_decay/>
      <sensor name='rear_hokuyo_sensor' type='ray'>
        <visualize>0</visualize>
        <update_rate>34.5</update_rate>
        <ray>
          <scan>
            <horizontal>
              <samples>720</samples>
              <resolution>1</resolution>
              <min_angle>-1.5708</min_angle>
              <max_angle>1.5708</max_angle>
            </horizontal>
          </scan>
          <range>
            <min>0.023</min>
            <max>60</max>
            <resolution>0.001</resolution>
          </range>
          <noise>
            <type>gaussian</type>
            <mean>0</mean>
            <stddev>0.01</stddev>
          </noise>
        </ray>
        <plugin name='gazebo_ros_rear_hokuyo_controller' filename='libgazebo_ros_laser.so'>
          <topicName>/scan_rear</topicName>
          <frameName>base_laser_rear_link</frameName>
        </plugin>
        <pose frame=''>-0.2795 0 0.1335 -3.14159 -0 -3.14159</pose>
      </sensor>
      <gravity>1</gravity>
      <velocity_decay/>
      <self_collide>0</self_collide>
      <sensor name='front_hokuyo_sensor' type='ray'>
        <visualize>0</visualize>
        <update_rate>4.3</update_rate>
        <ray>
          <scan>
            <horizontal>
              <samples>512</samples>
              <resolution>1</resolution>
              <min_angle>-1.5708</min_angle>
              <max_angle>1.5708</max_angle>
            </horizontal>
          </scan>
          <range>
            <min>0.0199999</min>
            <max>5.6</max>
            <resolution>0.001</resolution>
          </range>
          <noise>
            <type>gaussian</type>
            <mean>0</mean>
            <stddev>0.01</stddev>
          </noise>
        </ray>
        <plugin name='gazebo_ros_front_hokuyo_controller' filename='libgazebo_ros_laser.so'>
          <topicName>/scan_front</topicName>
          <frameName>base_laser_front_link</frameName>
        </plugin>
        <pose frame=''>0.2785 0 0.1335 0 -0 0</pose>
      </sensor>
    </link>
    <link name='head_link'>
      <pose frame=''>0.05 0 0.765 0 -0 0</pose>
      <inertial>
        <pose frame=''>0.002353 0 0.00098 0 -0 0</pose>
        <mass>10.2</mass>
        <inertia>
          <ixx>0.101076</ixx>
          <ixy>0</ixy>
          <ixz>-0.00117147</ixz>
          <iyy>0.103345</iyy>
          <iyz>0</iyz>
          <izz>0.103409</izz>
        </inertia>
      </inertial>
      <collision name='head_link_collision'>
        <pose frame=''>0.025 0 0.15 0 -0 0</pose>
        <geometry>
          <box>
            <size>0.35 0.45 0.25</size>
          </box>
        </geometry>
        <surface>
          <contact>
            <ode/>
          </contact>
          <friction>
            <ode/>
          </friction>
        </surface>
      </collision>
      <collision name='head_link_fixed_joint_lump__neck_camera_model_link_collision_1'>
        <pose frame=''>0.12 0 0.05 0 0.8 0</pose>
        <geometry>
          <box>
            <size>0.035 0.185 0.025</size>
          </box>
        </geometry>
      </collision>
      <visual name='head_link_visual'>
        <pose frame=''>0 0 0 0 -0 0</pose>
        <geometry>
          <mesh>
            <scale>1 1 1</scale>
            <uri>model://mbot_description/meshes/head/mbot_head.dae</uri>
          </mesh>
        </geometry>
        <material>
          <script>
            <name>Gazebo/DepthMapVS</name>
            <uri>file://media/materials/scripts/gazebo.material</uri>
          </script>
        </material>
      </visual>
      <visual name='head_link_fixed_joint_lump__neck_camera_model_link_visual_1'>
        <pose frame=''>0.146898 0 0.051729 0 0.8 0</pose>
        <geometry>
          <mesh>
            <scale>1 1 1</scale>
            <uri>model://mbot_description/meshes/sensors/asus_camera_simple.dae</uri>
          </mesh>
        </geometry>
      </visual>
      <velocity_decay/>
      <gravity>1</gravity>
      <gravity>1</gravity>
      <velocity_decay/>
      <self_collide>0</self_collide>
      <sensor name='neck_camera' type='depth'>
        <always_on>1</always_on>
        <update_rate>20</update_rate>
        <camera name='__default__'>
          <horizontal_fov>1.0472</horizontal_fov>
          <image>
            <format>B8G8R8</format>
            <width>640</width>
            <height>480</height>
          </image>
          <clip>
            <near>0.05</near>
            <far>8</far>
          </clip>
        </camera>
        <plugin name='neck_camera_camera_controller' filename='libgazebo_ros_openni_kinect.so'>
          <cameraName>neck_camera</cameraName>
          <alwaysOn>true</alwaysOn>
          <updateRate>10</updateRate>
          <imageTopicName>rgb/image_raw</imageTopicName>
          <depthImageTopicName>depth/image_raw</depthImageTopicName>
          <pointCloudTopicName>depth_registered/points</pointCloudTopicName>
          <cameraInfoTopicName>rgb/camera_info</cameraInfoTopicName>
          <depthImageCameraInfoTopicName>depth/camera_info</depthImageCameraInfoTopicName>
          <frameName>neck_camera_depth_optical_frame</frameName>
          <baseline>0.1</baseline>
          <distortion_k1>0.0</distortion_k1>
          <distortion_k2>0.0</distortion_k2>
          <distortion_k3>0.0</distortion_k3>
          <distortion_t1>0.0</distortion_t1>
          <distortion_t2>0.0</distortion_t2>
          <pointCloudCutoff>0.4</pointCloudCutoff>
        </plugin>
        <pose frame=''>0.177476 0.048777 0.044032 -0.00322 0.797828 0.093157</pose>
      </sensor>
    </link>
    <joint name='base_link_to_head_link_joint' type='revolute'>
      <child>head_link</child>
      <parent>base_link</parent>
      <axis>
        <xyz>0 0 -1</xyz>
        <limit>
          <lower>-1.5708</lower>
          <upper>1.5708</upper>
          <effort>100</effort>
          <velocity>1</velocity>
        </limit>
        <dynamics>
          <spring_reference>0</spring_reference>
          <spring_stiffness>0</spring_stiffness>
        </dynamics>
        <use_parent_model_frame>1</use_parent_model_frame>
      </axis>
    </joint>
    <link name='head_camera_model_link'>
      <pose frame=''>0.16 0 1.04 0 1.05 0</pose>
      <inertial>
        <pose frame=''>0 0 0 0 -0 0</pose>
        <mass>0.2</mass>
        <inertia>
          <ixx>0.00058083</ixx>
          <ixy>0</ixy>
          <ixz>0</ixz>
          <iyy>3.0833e-05</iyy>
          <iyz>0</iyz>
          <izz>0.00059083</izz>
        </inertia>
      </inertial>
      <collision name='head_camera_model_link_collision'>
        <pose frame=''>0 0 0 0 -0 0</pose>
        <geometry>
          <box>
            <size>0.035 0.185 0.025</size>
          </box>
        </geometry>
      </collision>
      <visual name='head_camera_model_link_visual'>
        <pose frame=''>0.0175 0 0.0205 0 -0 0</pose>
        <geometry>
          <mesh>
            <scale>1 1 1</scale>
            <uri>model://mbot_description/meshes/sensors/asus_camera_simple.dae</uri>
          </mesh>
        </geometry>
      </visual>
      <gravity>1</gravity>
      <velocity_decay/>
      <self_collide>0</self_collide>
      <sensor name='head_camera' type='depth'>
        <always_on>1</always_on>
        <update_rate>20</update_rate>
        <camera name='__default__'>
          <horizontal_fov>1.0472</horizontal_fov>
          <image>
            <format>B8G8R8</format>
            <width>640</width>
            <height>480</height>
          </image>
          <clip>
            <near>0.05</near>
            <far>8</far>
          </clip>
        </camera>
        <plugin name='head_camera_camera_controller' filename='libgazebo_ros_openni_kinect.so'>
          <cameraName>head_camera</cameraName>
          <alwaysOn>true</alwaysOn>
          <updateRate>10</updateRate>
          <imageTopicName>rgb/image_raw</imageTopicName>
          <depthImageTopicName>depth/image_raw</depthImageTopicName>
          <pointCloudTopicName>depth_registered/points</pointCloudTopicName>
          <cameraInfoTopicName>rgb/camera_info</cameraInfoTopicName>
          <depthImageCameraInfoTopicName>depth/camera_info</depthImageCameraInfoTopicName>
          <frameName>head_camera_depth_optical_frame</frameName>
          <baseline>0.1</baseline>
          <distortion_k1>0.0</distortion_k1>
          <distortion_k2>0.0</distortion_k2>
          <distortion_k3>0.0</distortion_k3>
          <distortion_t1>0.0</distortion_t1>
          <distortion_t2>0.0</distortion_t2>
          <pointCloudCutoff>0.4</pointCloudCutoff>
        </plugin>
        <pose frame=''>0.076011 0.048975 0.02001 -0.01 0.04 0.03</pose>
      </sensor>
    </link>
    <joint name='head_link_to_head_camera_link' type='revolute'>
      <child>head_camera_model_link</child>
      <parent>head_link</parent>
      <axis>
        <xyz>0 -1 0</xyz>
        <limit>
          <lower>0.523599</lower>
          <upper>1.658</upper>
          <effort>1</effort>
          <velocity>5.23599</velocity>
        </limit>
        <dynamics>
          <spring_reference>0</spring_reference>
          <spring_stiffness>0</spring_stiffness>
        </dynamics>
        <use_parent_model_frame>1</use_parent_model_frame>
      </axis>
    </joint>
    <link name='left_arm_shoulder_roll'>
      <pose frame=''>0.003 0.19315 0.62 1.5708 1.04934 3.14159</pose>
      <inertial>
        <pose frame=''>0 0 0 0 -0 0</pose>
        <mass>0.001</mass>
        <inertia>
          <ixx>0.1027</ixx>
          <ixy>0</ixy>
          <ixz>0</ixz>
          <iyy>0.1027</iyy>
          <iyz>0</iyz>
          <izz>0.1027</izz>
        </inertia>
      </inertial>
      <collision name='left_arm_shoulder_roll_collision'>
        <pose frame=''>0 0 0.0587 1.5708 -0 0</pose>
        <geometry>
          <box>
            <size>0.09829 0.18143 0.08392</size>
          </box>
        </geometry>
      </collision>
      <visual name='left_arm_shoulder_roll_visual'>
        <pose frame=''>0 0 0 1.5708 -0 0.384</pose>
        <geometry>
          <mesh>
            <scale>1 1 1</scale>
            <uri>model://cyton_gamma_1500_description/meshes/shoulder_roll.dae</uri>
          </mesh>
        </geometry>
      </visual>
    </link>
    <joint name='left_arm_joint0' type='revolute'>
      <child>left_arm_shoulder_roll</child>
      <parent>base_link</parent>
      <axis>
        <xyz>0 1 -0</xyz>
        <limit>
          <lower>-2.5509</lower>
          <upper>2.5585</upper>
          <effort>100</effort>
          <velocity>1</velocity>
        </limit>
        <dynamics>
          <spring_reference>0</spring_reference>
          <spring_stiffness>0</spring_stiffness>
        </dynamics>
        <use_parent_model_frame>1</use_parent_model_frame>
      </axis>
    </joint>
    <link name='left_arm_shoulder_pitch'>
      <pose frame=''>-0.007212 0.3175 0.602225 1.5708 1.04934 3.14159</pose>
      <inertial>
        <pose frame=''>0 0 0 0 -0 0</pose>
        <mass>0.001</mass>
        <inertia>
          <ixx>0.0827</ixx>
          <ixy>0</ixy>
          <ixz>0</ixz>
          <iyy>0.0827</iyy>
          <iyz>0</iyz>
          <izz>0.0827</izz>
        </inertia>
      </inertial>
      <collision name='left_arm_shoulder_pitch_collision'>
        <pose frame=''>-0.02 -0.001 0.064 1.5708 -0 0</pose>
        <geometry>
          <box>
            <size>0.0709 0.19363 0.083</size>
          </box>
        </geometry>
      </collision>
      <visual name='left_arm_shoulder_pitch_visual'>
        <pose frame=''>0 0 0 1.5708 -0 0</pose>
        <geometry>
          <mesh>
            <scale>1 1 1</scale>
            <uri>model://cyton_gamma_1500_description/meshes/shoulder_pitch.dae</uri>
          </mesh>
        </geometry>
      </visual>
    </link>
    <joint name='left_arm_joint1' type='revolute'>
      <child>left_arm_shoulder_pitch</child>
      <parent>left_arm_shoulder_roll</parent>
      <axis>
        <xyz>-0.498144 0 -0.867094</xyz>
        <limit>
          <lower>-1.707</lower>
          <upper>1.6379</upper>
          <effort>100</effort>
          <velocity>1</velocity>
        </limit>
        <dynamics>
          <spring_reference>0</spring_reference>
          <spring_stiffness>0</spring_stiffness>
        </dynamics>
        <use_parent_model_frame>1</use_parent_model_frame>
      </axis>
    </joint>
    <link name='left_arm_shoulder_yaw'>
      <pose frame=''>0.021274 0.443 0.610655 1.5708 1.04934 3.14159</pose>
      <inertial>
        <pose frame=''>0 0 0 0 -0 0</pose>
        <mass>0.001</mass>
        <inertia>
          <ixx>0.0627</ixx>
          <ixy>0</ixy>
          <ixz>0</ixz>
          <iyy>0.0627</iyy>
          <iyz>0</iyz>
          <izz>0.0627</izz>
        </inertia>
      </inertial>
      <collision name='left_arm_shoulder_yaw_collision'>
        <pose frame=''>-0.003 0.0225 0.057 1.5708 0 -1.5708</pose>
        <geometry>
          <box>
            <size>0.0717 0.1846 0.0756</size>
          </box>
        </geometry>
      </collision>
      <visual name='left_arm_shoulder_yaw_visual'>
        <pose frame=''>0 0 0 1.5708 0 -1.5708</pose>
        <geometry>
          <mesh>
            <scale>1 1 1</scale>
            <uri>model://cyton_gamma_1500_description/meshes/shoulder_yaw.dae</uri>
          </mesh>
        </geometry>
      </visual>
    </link>
    <joint name='left_arm_joint2' type='revolute'>
      <child>left_arm_shoulder_yaw</child>
      <parent>left_arm_shoulder_pitch</parent>
      <axis>
        <xyz>0.867094 -0 -0.498144</xyz>
        <limit>
          <lower>-1.5459</lower>
          <upper>1.73</upper>
          <effort>100</effort>
          <velocity>1</velocity>
        </limit>
        <dynamics>
          <spring_reference>0</spring_reference>
          <spring_stiffness>0</spring_stiffness>
        </dynamics>
        <use_parent_model_frame>1</use_parent_model_frame>
      </axis>
    </joint>
    <link name='left_arm_elbow_pitch'>
      <pose frame=''>-0.005555 0.5588 0.605309 1.5708 1.04934 3.14159</pose>
      <inertial>
        <pose frame=''>0 0 0 0 -0 0</pose>
        <mass>0.001</mass>
        <inertia>
          <ixx>0.0327</ixx>
          <ixy>0</ixy>
          <ixz>0</ixz>
          <iyy>0.0327</iyy>
          <iyz>0</iyz>
          <izz>0.0327</izz>
        </inertia>
      </inertial>
      <collision name='left_arm_elbow_pitch_collision'>
        <pose frame=''>-0.017 0.004 0.0461 1.5708 -0 -3.14159</pose>
        <geometry>
          <box>
            <size>0.0549 0.1557 0.076</size>
          </box>
        </geometry>
      </collision>
      <visual name='left_arm_elbow_pitch_visual'>
        <pose frame=''>0 0 0 1.5708 -0 -3.14159</pose>
        <geometry>
          <mesh>
            <scale>1 1 1</scale>
            <uri>model://cyton_gamma_1500_description/meshes/elbow_pitch.dae</uri>
          </mesh>
        </geometry>
      </visual>
    </link>
    <joint name='left_arm_joint3' type='revolute'>
      <child>left_arm_elbow_pitch</child>
      <parent>left_arm_shoulder_yaw</parent>
      <axis>
        <xyz>-0.498144 0 -0.867094</xyz>
        <limit>
          <lower>-1.6072</lower>
          <upper>1.6149</upper>
          <effort>100</effort>
          <velocity>1</velocity>
        </limit>
        <dynamics>
          <spring_reference>0</spring_reference>
          <spring_stiffness>0</spring_stiffness>
        </dynamics>
        <use_parent_model_frame>1</use_parent_model_frame>
      </axis>
    </joint>
    <link name='left_arm_elbow_yaw'>
      <pose frame=''>0.018571 0.65626 0.61117 1.5708 1.04934 3.14159</pose>
      <inertial>
        <pose frame=''>0 0 0 0 -0 0</pose>
        <mass>0.001</mass>
        <inertia>
          <ixx>0.0227</ixx>
          <ixy>0</ixy>
          <ixz>0</ixz>
          <iyy>0.0227</iyy>
          <iyz>0</iyz>
          <izz>0.0227</izz>
        </inertia>
      </inertial>
      <collision name='left_arm_elbow_yaw_collision'>
        <pose frame=''>0 0.0172 0.047 1.5708 -0 1.5708</pose>
        <geometry>
          <box>
            <size>0.0535 0.116 0.053</size>
          </box>
        </geometry>
      </collision>
      <visual name='left_arm_elbow_yaw_visual'>
        <pose frame=''>0 0 0 1.5708 -0 1.5708</pose>
        <geometry>
          <mesh>
            <scale>1 1 1</scale>
            <uri>model://cyton_gamma_1500_description/meshes/elbow_yaw.dae</uri>
          </mesh>
        </geometry>
      </visual>
    </link>
    <joint name='left_arm_joint4' type='revolute'>
      <child>left_arm_elbow_yaw</child>
      <parent>left_arm_elbow_pitch</parent>
      <axis>
        <xyz>0.867094 -0 -0.498144</xyz>
        <limit>
          <lower>-1.8757</lower>
          <upper>1.4615</upper>
          <effort>100</effort>
          <velocity>1</velocity>
        </limit>
        <dynamics>
          <spring_reference>0</spring_reference>
          <spring_stiffness>0</spring_stiffness>
        </dynamics>
        <use_parent_model_frame>1</use_parent_model_frame>
      </axis>
    </joint>
    <link name='left_arm_wrist_pitch'>
      <pose frame=''>0.016044 0.72806 0.642906 -1.5708 -1.04934 -0</pose>
      <inertial>
        <pose frame=''>0 0 0 0 -0 0</pose>
        <mass>0.001</mass>
        <inertia>
          <ixx>0.0127</ixx>
          <ixy>0</ixy>
          <ixz>0</ixz>
          <iyy>0.0127</iyy>
          <iyz>0</iyz>
          <izz>0.0127</izz>
        </inertia>
      </inertial>
      <collision name='left_arm_wrist_pitch_collision'>
        <pose frame=''>-0.02 0 0.05 1.5708 -0 1.5708</pose>
        <geometry>
          <box>
            <size>0.085 0.0435 0.05185</size>
          </box>
        </geometry>
      </collision>
      <visual name='left_arm_wrist_pitch_visual'>
        <pose frame=''>0 0 0 1.5708 -0 1.5708</pose>
        <geometry>
          <mesh>
            <scale>1 1 1</scale>
            <uri>model://cyton_gamma_1500_description/meshes/wrist_pitch.dae</uri>
          </mesh>
        </geometry>
      </visual>
    </link>
    <joint name='left_arm_joint5' type='revolute'>
      <child>left_arm_wrist_pitch</child>
      <parent>left_arm_elbow_yaw</parent>
      <axis>
        <xyz>-0.498144 0 -0.867094</xyz>
        <limit>
          <lower>-1.5766</lower>
          <upper>1.5382</upper>
          <effort>100</effort>
          <velocity>1</velocity>
        </limit>
        <dynamics>
          <spring_reference>0</spring_reference>
          <spring_stiffness>0</spring_stiffness>
        </dynamics>
        <use_parent_model_frame>1</use_parent_model_frame>
      </axis>
    </joint>
    <link name='left_arm_ist_gripper_mount'>
      <pose frame=''>0.002966 0.779485 0.620141 -1.5708 0.521457 -0</pose>
      <inertial>
        <pose frame=''>0 0 0 0 -0 0</pose>
        <mass>0.001</mass>
        <inertia>
          <ixx>0.0027</ixx>
          <ixy>0</ixy>
          <ixz>0</ixz>
          <iyy>0.0027</iyy>
          <iyz>0</iyz>
          <izz>0.0027</izz>
        </inertia>
      </inertial>
      <collision name='left_arm_ist_gripper_mount_collision'>
        <pose frame=''>-0.007 0.008 0.05 -3.14159 0 -1.5708</pose>
        <geometry>
          <box>
            <size>0.1 0.05 0.1</size>
          </box>
        </geometry>
      </collision>
      <visual name='left_arm_ist_gripper_mount_visual'>
        <pose frame=''>-0.018 -0.04 -0.019 0 -0 0</pose>
        <geometry>
          <mesh>
            <scale>1 1 1</scale>
            <uri>model://cyton_gamma_1500_description/meshes/ist_gripper_mount.dae</uri>
          </mesh>
        </geometry>
      </visual>
      <visual name='left_arm_ist_gripper_mount_fixed_joint_lump__left_arm_virtual_endeffector_visual_1'>
        <pose frame=''>0 0 0.17 0 -0 0</pose>
        <geometry>
          <sphere>
            <radius>0.002</radius>
          </sphere>
        </geometry>
      </visual>
    </link>
    <joint name='left_arm_joint6' type='revolute'>
      <child>left_arm_ist_gripper_mount</child>
      <parent>left_arm_wrist_pitch</parent>
      <axis>
        <xyz>0 1 -0</xyz>
        <limit>
          <lower>-2.5279</lower>
          <upper>2.5355</upper>
          <effort>100</effort>
          <velocity>1</velocity>
        </limit>
        <dynamics>
          <spring_reference>0</spring_reference>
          <spring_stiffness>0</spring_stiffness>
        </dynamics>
        <use_parent_model_frame>1</use_parent_model_frame>
      </axis>
    </joint>
    <link name='left_arm_gripper_finger1'>
      <pose frame=''>-0.008225 0.877485 0.667108 -3.14159 1.04934 3.14159</pose>
      <inertial>
        <pose frame=''>0 0 0 0 -0 0</pose>
        <mass>0.001</mass>
        <inertia>
          <ixx>0.0027</ixx>
          <ixy>0</ixy>
          <ixz>0</ixz>
          <iyy>0.0027</iyy>
          <iyz>0</iyz>
          <izz>0.0027</izz>
        </inertia>
      </inertial>
      <collision name='left_arm_gripper_finger1_collision'>
        <pose frame=''>-0.003 0.05 0.015 0 -0 0</pose>
        <geometry>
          <box>
            <size>0.04 0.14 0.04</size>
          </box>
        </geometry>
      </collision>
      <visual name='left_arm_gripper_finger1_visual'>
        <pose frame=''>0 0 0 0 -0 0</pose>
        <geometry>
          <mesh>
            <scale>1 1 1</scale>
            <uri>model://cyton_gamma_1500_description/meshes/ist_finger.dae</uri>
          </mesh>
        </geometry>
      </visual>
    </link>
    <joint name='left_arm_gripper_joint' type='revolute'>
      <child>left_arm_gripper_finger1</child>
      <parent>left_arm_ist_gripper_mount</parent>
      <axis>
        <xyz>0.867094 -0 -0.498144</xyz>
        <limit>
          <lower>-0.08</lower>
          <upper>0.5</upper>
          <effort>100</effort>
          <velocity>1</velocity>
        </limit>
        <dynamics>
          <spring_reference>0</spring_reference>
          <spring_stiffness>0</spring_stiffness>
        </dynamics>
        <use_parent_model_frame>1</use_parent_model_frame>
      </axis>
    </joint>
    <link name='left_arm_gripper_finger2'>
      <pose frame=''>-0.019648 0.877485 0.587001 -0 -1.04934 -0</pose>
      <inertial>
        <pose frame=''>0 0 0 0 -0 0</pose>
        <mass>0.001</mass>
        <inertia>
          <ixx>0.0027</ixx>
          <ixy>0</ixy>
          <ixz>0</ixz>
          <iyy>0.0027</iyy>
          <iyz>0</iyz>
          <izz>0.0027</izz>
        </inertia>
      </inertial>
      <collision name='left_arm_gripper_finger2_collision'>
        <pose frame=''>-0.003 0.05 0.015 0 -0 0</pose>
        <geometry>
          <box>
            <size>0.04 0.14 0.04</size>
          </box>
        </geometry>
      </collision>
      <visual name='left_arm_gripper_finger2_visual'>
        <pose frame=''>0 0 0 0 -0 0</pose>
        <geometry>
          <mesh>
            <scale>1 1 1</scale>
            <uri>model://cyton_gamma_1500_description/meshes/ist_finger.dae</uri>
          </mesh>
        </geometry>
      </visual>
    </link>
    <joint name='left_arm_gripper_joint2' type='revolute'>
      <child>left_arm_gripper_finger2</child>
      <parent>left_arm_ist_gripper_mount</parent>
      <axis>
        <xyz>-0.867094 0 0.498144</xyz>
        <limit>
          <lower>-0.08</lower>
          <upper>0.5</upper>
          <effort>100</effort>
          <velocity>1</velocity>
        </limit>
        <dynamics>
          <spring_reference>0</spring_reference>
          <spring_stiffness>0</spring_stiffness>
        </dynamics>
        <use_parent_model_frame>1</use_parent_model_frame>
      </axis>
    </joint>
    <link name='front_left_wheel_link'>
      <pose frame=''>-0.175 0.14429 0.05 0 -0 0</pose>
      <inertial>
        <pose frame=''>0 0 0 0 -0 0</pose>
        <mass>2.3</mass>
        <inertia>
          <ixx>0.0033212</ixx>
          <ixy>0</ixy>
          <ixz>0</ixz>
          <iyy>0.0066424</iyy>
          <iyz>0</iyz>
          <izz>0.0033212</izz>
        </inertia>
      </inertial>
      <collision name='front_left_wheel_link_collision'>
        <pose frame=''>0 0 0 1.5708 -0 0</pose>
        <geometry>
          <cylinder>
            <length>0.05</length>
            <radius>0.05</radius>
          </cylinder>
        </geometry>
        <surface>
          <contact>
            <ode/>
          </contact>
          <friction>
            <ode>
              <mu>0</mu>
              <mu2>0</mu2>
            </ode>
          </friction>
        </surface>
      </collision>
      <visual name='front_left_wheel_link_visual'>
        <pose frame=''>0 0 0 1.5708 -0 0</pose>
        <geometry>
          <cylinder>
            <length>0.05</length>
            <radius>0.05</radius>
          </cylinder>
        </geometry>
        <material>
          <script>
            <name>Gazebo/DarkGrey</name>
            <uri>file://media/materials/scripts/gazebo.material</uri>
          </script>
        </material>
      </visual>
      <gravity>1</gravity>
      <velocity_decay/>
      <self_collide>0</self_collide>
    </link>
    <joint name='front_left_wheel' type='revolute'>
      <child>front_left_wheel_link</child>
      <parent>base_link</parent>
      <axis>
        <xyz>0 1 0</xyz>
        <limit>
          <lower>-1e+16</lower>
          <upper>1e+16</upper>
        </limit>
        <dynamics>
          <spring_reference>0</spring_reference>
          <spring_stiffness>0</spring_stiffness>
        </dynamics>
        <use_parent_model_frame>1</use_parent_model_frame>
      </axis>
    </joint>
    <link name='front_right_wheel_link'>
      <pose frame=''>0.175 0.14429 0.05 0 -0 0</pose>
      <inertial>
        <pose frame=''>0 0 0 0 -0 0</pose>
        <mass>2.3</mass>
        <inertia>
          <ixx>0.0033212</ixx>
          <ixy>0</ixy>
          <ixz>0</ixz>
          <iyy>0.0066424</iyy>
          <iyz>0</iyz>
          <izz>0.0033212</izz>
        </inertia>
      </inertial>
      <collision name='front_right_wheel_link_collision'>
        <pose frame=''>0 0 0 1.5708 -0 0</pose>
        <geometry>
          <cylinder>
            <length>0.05</length>
            <radius>0.05</radius>
          </cylinder>
        </geometry>
        <surface>
          <contact>
            <ode/>
          </contact>
          <friction>
            <ode>
              <mu>0</mu>
              <mu2>0</mu2>
            </ode>
          </friction>
        </surface>
      </collision>
      <visual name='front_right_wheel_link_visual'>
        <pose frame=''>0 0 0 1.5708 -0 0</pose>
        <geometry>
          <cylinder>
            <length>0.05</length>
            <radius>0.05</radius>
          </cylinder>
        </geometry>
        <material>
          <script>
            <name>Gazebo/DarkGrey</name>
            <uri>file://media/materials/scripts/gazebo.material</uri>
          </script>
        </material>
      </visual>
      <gravity>1</gravity>
      <velocity_decay/>
      <self_collide>0</self_collide>
    </link>
    <joint name='front_right_wheel' type='revolute'>
      <child>front_right_wheel_link</child>
      <parent>base_link</parent>
      <axis>
        <xyz>0 1 0</xyz>
        <limit>
          <lower>-1e+16</lower>
          <upper>1e+16</upper>
        </limit>
        <dynamics>
          <spring_reference>0</spring_reference>
          <spring_stiffness>0</spring_stiffness>
        </dynamics>
        <use_parent_model_frame>1</use_parent_model_frame>
      </axis>
    </joint>
    <link name='rear_left_wheel_link'>
      <pose frame=''>-0.175 -0.14429 0.05 0 -0 0</pose>
      <inertial>
        <pose frame=''>0 0 0 0 -0 0</pose>
        <mass>2.3</mass>
        <inertia>
          <ixx>0.0033212</ixx>
          <ixy>0</ixy>
          <ixz>0</ixz>
          <iyy>0.0066424</iyy>
          <iyz>0</iyz>
          <izz>0.0033212</izz>
        </inertia>
      </inertial>
      <collision name='rear_left_wheel_link_collision'>
        <pose frame=''>0 0 0 1.5708 -0 0</pose>
        <geometry>
          <cylinder>
            <length>0.05</length>
            <radius>0.05</radius>
          </cylinder>
        </geometry>
        <surface>
          <contact>
            <ode/>
          </contact>
          <friction>
            <ode>
              <mu>0</mu>
              <mu2>0</mu2>
            </ode>
          </friction>
        </surface>
      </collision>
      <visual name='rear_left_wheel_link_visual'>
        <pose frame=''>0 0 0 1.5708 -0 0</pose>
        <geometry>
          <cylinder>
            <length>0.05</length>
            <radius>0.05</radius>
          </cylinder>
        </geometry>
        <material>
          <script>
            <name>Gazebo/DarkGrey</name>
            <uri>file://media/materials/scripts/gazebo.material</uri>
          </script>
        </material>
      </visual>
      <gravity>1</gravity>
      <velocity_decay/>
      <self_collide>0</self_collide>
    </link>
    <joint name='rear_left_wheel' type='revolute'>
      <child>rear_left_wheel_link</child>
      <parent>base_link</parent>
      <axis>
        <xyz>0 1 0</xyz>
        <limit>
          <lower>-1e+16</lower>
          <upper>1e+16</upper>
        </limit>
        <dynamics>
          <spring_reference>0</spring_reference>
          <spring_stiffness>0</spring_stiffness>
        </dynamics>
        <use_parent_model_frame>1</use_parent_model_frame>
      </axis>
    </joint>
    <link name='rear_right_wheel_link'>
      <pose frame=''>0.175 -0.14429 0.05 0 -0 0</pose>
      <inertial>
        <pose frame=''>0 0 0 0 -0 0</pose>
        <mass>2.3</mass>
        <inertia>
          <ixx>0.0033212</ixx>
          <ixy>0</ixy>
          <ixz>0</ixz>
          <iyy>0.0066424</iyy>
          <iyz>0</iyz>
          <izz>0.0033212</izz>
        </inertia>
      </inertial>
      <collision name='rear_right_wheel_link_collision'>
        <pose frame=''>0 0 0 1.5708 -0 0</pose>
        <geometry>
          <cylinder>
            <length>0.05</length>
            <radius>0.05</radius>
          </cylinder>
        </geometry>
        <surface>
          <contact>
            <ode/>
          </contact>
          <friction>
            <ode>
              <mu>0</mu>
              <mu2>0</mu2>
            </ode>
          </friction>
        </surface>
      </collision>
      <visual name='rear_right_wheel_link_visual'>
        <pose frame=''>0 0 0 1.5708 -0 0</pose>
        <geometry>
          <cylinder>
            <length>0.05</length>
            <radius>0.05</radius>
          </cylinder>
        </geometry>
        <material>
          <script>
            <name>Gazebo/DarkGrey</name>
            <uri>file://media/materials/scripts/gazebo.material</uri>
          </script>
        </material>
      </visual>
      <gravity>1</gravity>
      <velocity_decay/>
      <self_collide>0</self_collide>
    </link>
    <joint name='rear_right_wheel' type='revolute'>
      <child>rear_right_wheel_link</child>
      <parent>base_link</parent>
      <axis>
        <xyz>0 1 0</xyz>
        <limit>
          <lower>-1e+16</lower>
          <upper>1e+16</upper>
        </limit>
        <dynamics>
          <spring_reference>0</spring_reference>
          <spring_stiffness>0</spring_stiffness>
        </dynamics>
        <use_parent_model_frame>1</use_parent_model_frame>
      </axis>
    </joint>
    <plugin name='joint_state_publisher' filename='libgazebo_ros_joint_state_publisher.so'>
      <jointName>left_arm_joint0, left_arm_joint1, left_arm_joint2, left_arm_joint3, left_arm_joint4, left_arm_joint5, left_arm_joint6</jointName>
      <robotNamespace>/</robotNamespace>
      <updateRate>50.0</updateRate>
    </plugin>
    <static>0</static>
    <plugin name='gazebo_ros_control' filename='libgazebo_ros_control.so'/>
    <plugin name='ridgeback_ros_force_based_move' filename='libridgeback_ros_force_based_move.so'>
      <commandTopic>cmd_vel</commandTopic>
      <odometryTopic>differential_odom</odometryTopic>
      <odometryFrame>odom</odometryFrame>
      <odometryRate>25.0</odometryRate>
      <robotBaseFrame>base_link</robotBaseFrame>
      <cmdVelTimeOut>0.25</cmdVelTimeOut>
      <publishOdometryTf>0</publishOdometryTf>
      <yaw_velocity_p_gain>500.0</yaw_velocity_p_gain>
      <x_velocity_p_gain>10000.0</x_velocity_p_gain>
      <y_velocity_p_gain>10000.0</y_velocity_p_gain>
    </plugin>
  </model>
</sdf>
